#VRML_SIM R2023a utf8

EXTERNPROTO "https://raw.githubusercontent.com/cyberbotics/webots/R2023a/projects/objects/backgrounds/protos/TexturedBackground.proto"
EXTERNPROTO "https://raw.githubusercontent.com/cyberbotics/webots/R2023a/projects/objects/backgrounds/protos/TexturedBackgroundLight.proto"
EXTERNPROTO "https://raw.githubusercontent.com/cyberbotics/webots/R2023a/projects/objects/floors/protos/CircleArena.proto"
EXTERNPROTO "https://raw.githubusercontent.com/cyberbotics/webots/R2023a/projects/appearances/protos/VarnishedPine.proto"

WorldInfo {
}
Viewpoint {
  orientation 0.13031659499533216 -0.06159135455394561 -0.9895575223871691 4.7616970611851706
  position 0.12662240862134375 -1.8659998162827443 0.7309726852737694
}
TexturedBackground {
}
TexturedBackgroundLight {
}
CircleArena {
}
Robot {
  translation 0 0 0.74
  children [
    DEF right_back HingeJoint {
      jointParameters HingeJointParameters {
        position -0.32046070676779914
        axis 0 1 0
        anchor -0.2 -0.175 0
      }
      endPoint Solid {
        translation -0.2 -0.175 -0.15000000000000016
        rotation 0 1 0 0
        children [
          HingeJoint {
            jointParameters HingeJointParameters {
              position 0.6095776284906076
              axis 0 1 0
              anchor 0 0 -0.15
            }
            endPoint Solid {
              translation 0.09999999999999987 0 -0.2617999999999999
              rotation 0 -1 0 0.7296999999999996
              children [
                HingeJoint {
                  jointParameters HingeJointParameters {
                    position 5.751654393233611
                    axis 0 1 0
                    anchor 0 0 -0.15
                  }
                  endPoint DEF wheel_body Solid {
                    translation 0 -0.049999999999999975 -0.15
                    rotation -0.9331912630351962 0.25422127706764097 -0.2540189144155867 4.644093359790522
                    children [
                      HingeJoint {
                        jointParameters HingeJointParameters {
                          position -6.37907401275438
                          axis 0 0 -1
                          anchor 0 0 -0.05
                        }
                        endPoint SolidReference {
                          solidName "R_F_small_body"
                        }
                      }
                      DEF wheel_shape Shape {
                        appearance PBRAppearance {
                          baseColor 1 1 0
                        }
                        geometry Cylinder {
                          height 0.05
                          radius 0.1
                        }
                      }
                    ]
                    boundingObject USE wheel_shape
                    physics Physics {
                    }
                  }
                }
                DEF R_B_small_shape Shape {
                  appearance PBRAppearance {
                    baseColor 1 0 1
                  }
                  geometry Box {
                    size 0.05 0.05 0.3
                  }
                }
              ]
              boundingObject USE R_B_small_shape
              physics Physics {
              }
            }
          }
          DEF R_B_Big_shape Shape {
            appearance PBRAppearance {
              baseColor 0 1 1
            }
            geometry Box {
              size 0.05 0.05 0.3
            }
          }
        ]
        boundingObject USE R_B_Big_shape
        physics Physics {
        }
      }
    }
    DEF left_back HingeJoint {
      jointParameters HingeJointParameters {
        position 5.97081847491192
        axis 0 1 0
        anchor -0.2 0.175 0
      }
      endPoint Solid {
        translation -0.2 0.175 -0.1499999999999998
        rotation 0 1 0 0
        children [
          HingeJoint {
            jointParameters HingeJointParameters {
              position 0.7743651037141631
              axis 0 1 0
              anchor 0 0 -0.15
            }
            endPoint Solid {
              translation 0.10000000000000012 0 -0.2618000000000001
              rotation 0 -1 0 0.7296999999999996
              children [
                HingeJoint {
                  jointParameters HingeJointParameters {
                    position 17.780087006489186
                    axis 0 1 0
                    anchor 0 0 -0.15
                  }
                  endPoint DEF wheel_body Solid {
                    translation 0 0.05000000000000002 -0.15
                    rotation -0.7664726165689952 0.4543392061709115 -0.453977547667133 4.450282699709592
                    children [
                      HingeJoint {
                        jointParameters HingeJointParameters {
                          position -24.943727118933303
                          axis 0 0 -1
                          anchor 0 0 0.05
                        }
                        endPoint SolidReference {
                          solidName "L_F_small_body"
                        }
                      }
                      DEF wheel_shape Shape {
                        appearance PBRAppearance {
                          baseColor 1 1 0
                        }
                        geometry Cylinder {
                          height 0.05
                          radius 0.1
                        }
                      }
                    ]
                    boundingObject USE wheel_shape
                    physics Physics {
                    }
                  }
                }
                DEF L_B_small_shape Shape {
                  appearance PBRAppearance {
                    baseColor 1 0 1
                  }
                  geometry Box {
                    size 0.05 0.05 0.3
                  }
                }
              ]
              boundingObject USE L_B_small_shape
              physics Physics {
              }
            }
          }
          DEF L_B_Big_shape Shape {
            appearance PBRAppearance {
              baseColor 0 1 1
            }
            geometry Box {
              size 0.05 0.05 0.3
            }
          }
        ]
        name "solid(2)"
        boundingObject USE L_B_Big_shape
        physics Physics {
        }
      }
    }
    DEF right_front HingeJoint {
      jointParameters HingeJointParameters {
        position 0.25775820851761017
        axis 0 1 0
        anchor 0.2 -0.175 0
      }
      endPoint Solid {
        translation 0.2 -0.175 -0.15
        rotation 0 1 0 0
        children [
          HingeJoint {
            jointParameters HingeJointParameters {
              position -0.5960609517788641
              axis 0 1 0
              anchor 0 0 -0.15
            }
            endPoint DEF R_B_small_body Solid {
              translation -0.09999999999999996 0 -0.2617999999999999
              rotation 0 1 0 0.7297000000000008
              children [
                DEF R_F_small_shape Shape {
                  appearance PBRAppearance {
                    baseColor 1 0 1
                  }
                  geometry Box {
                    size 0.05 0.05 0.3
                  }
                }
              ]
              name "R_F_small_body"
              boundingObject USE R_F_small_shape
              physics Physics {
              }
            }
          }
          DEF R_F_Big_shape Shape {
            appearance PBRAppearance {
              baseColor 0 1 1
            }
            geometry Box {
              size 0.05 0.05 0.3
            }
          }
        ]
        name "solid(1)"
        boundingObject USE R_F_Big_shape
        physics Physics {
        }
      }
    }
    DEF left_front HingeJoint {
      jointParameters HingeJointParameters {
        position 0.3553347928199937
        axis 0 1 0
        anchor 0.2 0.175 0
      }
      endPoint Solid {
        translation 0.19999999999999996 0.175 -0.15000000000000013
        rotation 0 1 0 0
        children [
          HingeJoint {
            jointParameters HingeJointParameters {
              position -0.7737917869848858
              axis 0 1 0
              anchor 0 0 -0.15
            }
            endPoint DEF L_B_small_body Solid {
              translation -0.10000000000000016 0 -0.2618000000000002
              rotation 0 1 0 0.7297000000000002
              children [
                DEF L_F_small_shape Shape {
                  appearance PBRAppearance {
                    baseColor 1 0 1
                  }
                  geometry Box {
                    size 0.05 0.05 0.3
                  }
                }
              ]
              name "L_F_small_body"
              boundingObject USE L_F_small_shape
              physics Physics {
              }
            }
          }
          DEF L_F_Big_shape Shape {
            appearance PBRAppearance {
              baseColor 0 1 1
            }
            geometry Box {
              size 0.05 0.05 0.3
            }
          }
        ]
        name "solid(3)"
        boundingObject USE L_F_Big_shape
        physics Physics {
        }
      }
    }
    DEF Body_shape Shape {
      appearance VarnishedPine {
      }
      geometry Box {
        size 0.4 0.3 0.2
      }
    }
  ]
  name "Meow"
  boundingObject USE Body_shape
}
